<?xml version='1.0' encoding='utf-8'?>
<mujoco model="scene">
  <compiler autolimits="true" angle="degree" />
  <option integrator="implicitfast" timestep="0.002">
    <flag multiccd="disable" />
  </option>
  <default>
    <geom type="capsule" size="0.0075 0.01" mass="0.4" condim="6" />
  </default>
  <visual>
    <headlight diffuse="0.6 0.6 0.6" ambient="0.3 0.3 0.3" specular="0 0 0" />
    <rgba haze="0.15 0.25 0.35 1" />
    <global fovy="58" azimuth="0" elevation="90" offwidth="1920" offheight="1080" />
  </visual>
  <statistic center="0.13125 0.1407285 1.5" extent="0.85" />
  <asset>
    <texture type="skybox" builtin="gradient" rgb1="0.3 0.5 0.7" rgb2="0 0 0" width="512" height="3072" />
    <texture type="2d" name="groundplane" builtin="checker" mark="edge" rgb1="0.2 0.3 0.4" rgb2="0.1 0.2 0.3" markrgb="0.8 0.8 0.8" width="300" height="300" />
    <material name="groundplane" texture="groundplane" texuniform="true" texrepeat="5 5" reflectance="0.2" />
    <material name="collision_material" rgba="0 0 0 0" />
    <material name="visual_material" rgba="0 0 1 0.3" />
    <texture name="generic_obj" file="config/assets/texture.png" type="2d" />
    <material name="generic_obj" texture="generic_obj" specular="0.5" shininess="0.5" />
    <mesh file="config/assets/block.obj" scale="1 1 1" />
    <mesh file="config/assets/cross.obj" scale="1 1 1" />
    <mesh file="config/assets/diamond.obj" scale="1 1 1" />
    <mesh file="config/assets/hexagon.obj" scale="1 1 1" />
    <mesh file="config/assets/star.obj" scale="1 1 1" />
    <mesh file="config/assets/triangle.obj" scale="1 1 1" />
    <mesh file="config/assets/parallelogram.obj" scale="1 1 1" />
    <mesh file="config/assets/semicircle.obj" scale="1 1 1" />
    <mesh file="config/assets/trapezium.obj" scale="1 1 1" />
    <mesh file="config/assets/disc.obj" scale="1 1 1" />
  </asset>
  <worldbody>
    <light pos="0 0 1.5" dir="0 0 -1" directional="true" />
    <geom name="floor" size="0 0 0.05" type="plane" material="groundplane" />
    <body name="fingertip_0" pos="0.000000 0.000000 1.100000">
      <geom rgba="1 0 0 1" />
      <joint name="fingertip_0_x" type="slide" axis="1 0 0" limited="true" range="-0.03 0.03" />
      <joint name="fingertip_0_y" type="slide" axis="0 1 0" limited="true" range="-0.03 0.03" />
      <joint name="fingertip_0_z" type="slide" axis="0 0 1" limited="true" range="0.015 0.2" />
    </body>
    <body name="fingertip_1" pos="0.000000 0.043301 1.100000">
      <geom rgba="1 0 0 1" />
      <joint name="fingertip_1_x" type="slide" axis="1 0 0" limited="true" range="-0.03 0.03" />
      <joint name="fingertip_1_y" type="slide" axis="0 1 0" limited="true" range="-0.03 0.03" />
      <joint name="fingertip_1_z" type="slide" axis="0 0 1" limited="true" range="0.015 0.2" />
    </body>
    <body name="fingertip_2" pos="0.000000 0.086602 1.100000">
      <geom rgba="1 0 0 1" />
      <joint name="fingertip_2_x" type="slide" axis="1 0 0" limited="true" range="-0.03 0.03" />
      <joint name="fingertip_2_y" type="slide" axis="0 1 0" limited="true" range="-0.03 0.03" />
      <joint name="fingertip_2_z" type="slide" axis="0 0 1" limited="true" range="0.015 0.2" />
    </body>
    <body name="fingertip_3" pos="0.000000 0.129903 1.100000">
      <geom rgba="1 0 0 1" />
      <joint name="fingertip_3_x" type="slide" axis="1 0 0" limited="true" range="-0.03 0.03" />
      <joint name="fingertip_3_y" type="slide" axis="0 1 0" limited="true" range="-0.03 0.03" />
      <joint name="fingertip_3_z" type="slide" axis="0 0 1" limited="true" range="0.015 0.2" />
    </body>
    <body name="fingertip_4" pos="0.000000 0.173204 1.100000">
      <geom rgba="1 0 0 1" />
      <joint name="fingertip_4_x" type="slide" axis="1 0 0" limited="true" range="-0.03 0.03" />
      <joint name="fingertip_4_y" type="slide" axis="0 1 0" limited="true" range="-0.03 0.03" />
      <joint name="fingertip_4_z" type="slide" axis="0 0 1" limited="true" range="0.015 0.2" />
    </body>
    <body name="fingertip_5" pos="0.000000 0.216505 1.100000">
      <geom rgba="1 0 0 1" />
      <joint name="fingertip_5_x" type="slide" axis="1 0 0" limited="true" range="-0.03 0.03" />
      <joint name="fingertip_5_y" type="slide" axis="0 1 0" limited="true" range="-0.03 0.03" />
      <joint name="fingertip_5_z" type="slide" axis="0 0 1" limited="true" range="0.015 0.2" />
    </body>
    <body name="fingertip_6" pos="0.000000 0.259806 1.100000">
      <geom rgba="1 0 0 1" />
      <joint name="fingertip_6_x" type="slide" axis="1 0 0" limited="true" range="-0.03 0.03" />
      <joint name="fingertip_6_y" type="slide" axis="0 1 0" limited="true" range="-0.03 0.03" />
      <joint name="fingertip_6_z" type="slide" axis="0 0 1" limited="true" range="0.015 0.2" />
    </body>
    <body name="fingertip_7" pos="0.000000 0.303107 1.100000">
      <geom rgba="1 0 0 1" />
      <joint name="fingertip_7_x" type="slide" axis="1 0 0" limited="true" range="-0.03 0.03" />
      <joint name="fingertip_7_y" type="slide" axis="0 1 0" limited="true" range="-0.03 0.03" />
      <joint name="fingertip_7_z" type="slide" axis="0 0 1" limited="true" range="0.015 0.2" />
    </body>
    <body name="fingertip_8" pos="0.037500 -0.021650 1.100000">
      <geom rgba="1 0 0 1" />
      <joint name="fingertip_8_x" type="slide" axis="1 0 0" limited="true" range="-0.03 0.03" />
      <joint name="fingertip_8_y" type="slide" axis="0 1 0" limited="true" range="-0.03 0.03" />
      <joint name="fingertip_8_z" type="slide" axis="0 0 1" limited="true" range="0.015 0.2" />
    </body>
    <body name="fingertip_9" pos="0.037500 0.021651 1.100000">
      <geom rgba="1 0 0 1" />
      <joint name="fingertip_9_x" type="slide" axis="1 0 0" limited="true" range="-0.03 0.03" />
      <joint name="fingertip_9_y" type="slide" axis="0 1 0" limited="true" range="-0.03 0.03" />
      <joint name="fingertip_9_z" type="slide" axis="0 0 1" limited="true" range="0.015 0.2" />
    </body>
    <body name="fingertip_10" pos="0.037500 0.064952 1.100000">
      <geom rgba="1 0 0 1" />
      <joint name="fingertip_10_x" type="slide" axis="1 0 0" limited="true" range="-0.03 0.03" />
      <joint name="fingertip_10_y" type="slide" axis="0 1 0" limited="true" range="-0.03 0.03" />
      <joint name="fingertip_10_z" type="slide" axis="0 0 1" limited="true" range="0.015 0.2" />
    </body>
    <body name="fingertip_11" pos="0.037500 0.108253 1.100000">
      <geom rgba="1 0 0 1" />
      <joint name="fingertip_11_x" type="slide" axis="1 0 0" limited="true" range="-0.03 0.03" />
      <joint name="fingertip_11_y" type="slide" axis="0 1 0" limited="true" range="-0.03 0.03" />
      <joint name="fingertip_11_z" type="slide" axis="0 0 1" limited="true" range="0.015 0.2" />
    </body>
    <body name="fingertip_12" pos="0.037500 0.151554 1.100000">
      <geom rgba="1 0 0 1" />
      <joint name="fingertip_12_x" type="slide" axis="1 0 0" limited="true" range="-0.03 0.03" />
      <joint name="fingertip_12_y" type="slide" axis="0 1 0" limited="true" range="-0.03 0.03" />
      <joint name="fingertip_12_z" type="slide" axis="0 0 1" limited="true" range="0.015 0.2" />
    </body>
    <body name="fingertip_13" pos="0.037500 0.194855 1.100000">
      <geom rgba="1 0 0 1" />
      <joint name="fingertip_13_x" type="slide" axis="1 0 0" limited="true" range="-0.03 0.03" />
      <joint name="fingertip_13_y" type="slide" axis="0 1 0" limited="true" range="-0.03 0.03" />
      <joint name="fingertip_13_z" type="slide" axis="0 0 1" limited="true" range="0.015 0.2" />
    </body>
    <body name="fingertip_14" pos="0.037500 0.238156 1.100000">
      <geom rgba="1 0 0 1" />
      <joint name="fingertip_14_x" type="slide" axis="1 0 0" limited="true" range="-0.03 0.03" />
      <joint name="fingertip_14_y" type="slide" axis="0 1 0" limited="true" range="-0.03 0.03" />
      <joint name="fingertip_14_z" type="slide" axis="0 0 1" limited="true" range="0.015 0.2" />
    </body>
    <body name="fingertip_15" pos="0.037500 0.281457 1.100000">
      <geom rgba="1 0 0 1" />
      <joint name="fingertip_15_x" type="slide" axis="1 0 0" limited="true" range="-0.03 0.03" />
      <joint name="fingertip_15_y" type="slide" axis="0 1 0" limited="true" range="-0.03 0.03" />
      <joint name="fingertip_15_z" type="slide" axis="0 0 1" limited="true" range="0.015 0.2" />
    </body>
    <body name="fingertip_16" pos="0.075000 0.000000 1.100000">
      <geom rgba="1 0 0 1" />
      <joint name="fingertip_16_x" type="slide" axis="1 0 0" limited="true" range="-0.03 0.03" />
      <joint name="fingertip_16_y" type="slide" axis="0 1 0" limited="true" range="-0.03 0.03" />
      <joint name="fingertip_16_z" type="slide" axis="0 0 1" limited="true" range="0.015 0.2" />
    </body>
    <body name="fingertip_17" pos="0.075000 0.043301 1.100000">
      <geom rgba="1 0 0 1" />
      <joint name="fingertip_17_x" type="slide" axis="1 0 0" limited="true" range="-0.03 0.03" />
      <joint name="fingertip_17_y" type="slide" axis="0 1 0" limited="true" range="-0.03 0.03" />
      <joint name="fingertip_17_z" type="slide" axis="0 0 1" limited="true" range="0.015 0.2" />
    </body>
    <body name="fingertip_18" pos="0.075000 0.086602 1.100000">
      <geom rgba="1 0 0 1" />
      <joint name="fingertip_18_x" type="slide" axis="1 0 0" limited="true" range="-0.03 0.03" />
      <joint name="fingertip_18_y" type="slide" axis="0 1 0" limited="true" range="-0.03 0.03" />
      <joint name="fingertip_18_z" type="slide" axis="0 0 1" limited="true" range="0.015 0.2" />
    </body>
    <body name="fingertip_19" pos="0.075000 0.129903 1.100000">
      <geom rgba="1 0 0 1" />
      <joint name="fingertip_19_x" type="slide" axis="1 0 0" limited="true" range="-0.03 0.03" />
      <joint name="fingertip_19_y" type="slide" axis="0 1 0" limited="true" range="-0.03 0.03" />
      <joint name="fingertip_19_z" type="slide" axis="0 0 1" limited="true" range="0.015 0.2" />
    </body>
    <body name="fingertip_20" pos="0.075000 0.173204 1.100000">
      <geom rgba="1 0 0 1" />
      <joint name="fingertip_20_x" type="slide" axis="1 0 0" limited="true" range="-0.03 0.03" />
      <joint name="fingertip_20_y" type="slide" axis="0 1 0" limited="true" range="-0.03 0.03" />
      <joint name="fingertip_20_z" type="slide" axis="0 0 1" limited="true" range="0.015 0.2" />
    </body>
    <body name="fingertip_21" pos="0.075000 0.216505 1.100000">
      <geom rgba="1 0 0 1" />
      <joint name="fingertip_21_x" type="slide" axis="1 0 0" limited="true" range="-0.03 0.03" />
      <joint name="fingertip_21_y" type="slide" axis="0 1 0" limited="true" range="-0.03 0.03" />
      <joint name="fingertip_21_z" type="slide" axis="0 0 1" limited="true" range="0.015 0.2" />
    </body>
    <body name="fingertip_22" pos="0.075000 0.259806 1.100000">
      <geom rgba="1 0 0 1" />
      <joint name="fingertip_22_x" type="slide" axis="1 0 0" limited="true" range="-0.03 0.03" />
      <joint name="fingertip_22_y" type="slide" axis="0 1 0" limited="true" range="-0.03 0.03" />
      <joint name="fingertip_22_z" type="slide" axis="0 0 1" limited="true" range="0.015 0.2" />
    </body>
    <body name="fingertip_23" pos="0.075000 0.303107 1.100000">
      <geom rgba="1 0 0 1" />
      <joint name="fingertip_23_x" type="slide" axis="1 0 0" limited="true" range="-0.03 0.03" />
      <joint name="fingertip_23_y" type="slide" axis="0 1 0" limited="true" range="-0.03 0.03" />
      <joint name="fingertip_23_z" type="slide" axis="0 0 1" limited="true" range="0.015 0.2" />
    </body>
    <body name="fingertip_24" pos="0.112500 -0.021650 1.100000">
      <geom rgba="1 0 0 1" />
      <joint name="fingertip_24_x" type="slide" axis="1 0 0" limited="true" range="-0.03 0.03" />
      <joint name="fingertip_24_y" type="slide" axis="0 1 0" limited="true" range="-0.03 0.03" />
      <joint name="fingertip_24_z" type="slide" axis="0 0 1" limited="true" range="0.015 0.2" />
    </body>
    <body name="fingertip_25" pos="0.112500 0.021651 1.100000">
      <geom rgba="1 0 0 1" />
      <joint name="fingertip_25_x" type="slide" axis="1 0 0" limited="true" range="-0.03 0.03" />
      <joint name="fingertip_25_y" type="slide" axis="0 1 0" limited="true" range="-0.03 0.03" />
      <joint name="fingertip_25_z" type="slide" axis="0 0 1" limited="true" range="0.015 0.2" />
    </body>
    <body name="fingertip_26" pos="0.112500 0.064952 1.100000">
      <geom rgba="1 0 0 1" />
      <joint name="fingertip_26_x" type="slide" axis="1 0 0" limited="true" range="-0.03 0.03" />
      <joint name="fingertip_26_y" type="slide" axis="0 1 0" limited="true" range="-0.03 0.03" />
      <joint name="fingertip_26_z" type="slide" axis="0 0 1" limited="true" range="0.015 0.2" />
    </body>
    <body name="fingertip_27" pos="0.112500 0.108253 1.100000">
      <geom rgba="1 0 0 1" />
      <joint name="fingertip_27_x" type="slide" axis="1 0 0" limited="true" range="-0.03 0.03" />
      <joint name="fingertip_27_y" type="slide" axis="0 1 0" limited="true" range="-0.03 0.03" />
      <joint name="fingertip_27_z" type="slide" axis="0 0 1" limited="true" range="0.015 0.2" />
    </body>
    <body name="fingertip_28" pos="0.112500 0.151554 1.100000">
      <geom rgba="1 0 0 1" />
      <joint name="fingertip_28_x" type="slide" axis="1 0 0" limited="true" range="-0.03 0.03" />
      <joint name="fingertip_28_y" type="slide" axis="0 1 0" limited="true" range="-0.03 0.03" />
      <joint name="fingertip_28_z" type="slide" axis="0 0 1" limited="true" range="0.015 0.2" />
    </body>
    <body name="fingertip_29" pos="0.112500 0.194855 1.100000">
      <geom rgba="1 0 0 1" />
      <joint name="fingertip_29_x" type="slide" axis="1 0 0" limited="true" range="-0.03 0.03" />
      <joint name="fingertip_29_y" type="slide" axis="0 1 0" limited="true" range="-0.03 0.03" />
      <joint name="fingertip_29_z" type="slide" axis="0 0 1" limited="true" range="0.015 0.2" />
    </body>
    <body name="fingertip_30" pos="0.112500 0.238156 1.100000">
      <geom rgba="1 0 0 1" />
      <joint name="fingertip_30_x" type="slide" axis="1 0 0" limited="true" range="-0.03 0.03" />
      <joint name="fingertip_30_y" type="slide" axis="0 1 0" limited="true" range="-0.03 0.03" />
      <joint name="fingertip_30_z" type="slide" axis="0 0 1" limited="true" range="0.015 0.2" />
    </body>
    <body name="fingertip_31" pos="0.112500 0.281457 1.100000">
      <geom rgba="1 0 0 1" />
      <joint name="fingertip_31_x" type="slide" axis="1 0 0" limited="true" range="-0.03 0.03" />
      <joint name="fingertip_31_y" type="slide" axis="0 1 0" limited="true" range="-0.03 0.03" />
      <joint name="fingertip_31_z" type="slide" axis="0 0 1" limited="true" range="0.015 0.2" />
    </body>
    <body name="fingertip_32" pos="0.150000 0.000000 1.100000">
      <geom rgba="1 0 0 1" />
      <joint name="fingertip_32_x" type="slide" axis="1 0 0" limited="true" range="-0.03 0.03" />
      <joint name="fingertip_32_y" type="slide" axis="0 1 0" limited="true" range="-0.03 0.03" />
      <joint name="fingertip_32_z" type="slide" axis="0 0 1" limited="true" range="0.015 0.2" />
    </body>
    <body name="fingertip_33" pos="0.150000 0.043301 1.100000">
      <geom rgba="1 0 0 1" />
      <joint name="fingertip_33_x" type="slide" axis="1 0 0" limited="true" range="-0.03 0.03" />
      <joint name="fingertip_33_y" type="slide" axis="0 1 0" limited="true" range="-0.03 0.03" />
      <joint name="fingertip_33_z" type="slide" axis="0 0 1" limited="true" range="0.015 0.2" />
    </body>
    <body name="fingertip_34" pos="0.150000 0.086602 1.100000">
      <geom rgba="1 0 0 1" />
      <joint name="fingertip_34_x" type="slide" axis="1 0 0" limited="true" range="-0.03 0.03" />
      <joint name="fingertip_34_y" type="slide" axis="0 1 0" limited="true" range="-0.03 0.03" />
      <joint name="fingertip_34_z" type="slide" axis="0 0 1" limited="true" range="0.015 0.2" />
    </body>
    <body name="fingertip_35" pos="0.150000 0.129903 1.100000">
      <geom rgba="1 0 0 1" />
      <joint name="fingertip_35_x" type="slide" axis="1 0 0" limited="true" range="-0.03 0.03" />
      <joint name="fingertip_35_y" type="slide" axis="0 1 0" limited="true" range="-0.03 0.03" />
      <joint name="fingertip_35_z" type="slide" axis="0 0 1" limited="true" range="0.015 0.2" />
    </body>
    <body name="fingertip_36" pos="0.150000 0.173204 1.100000">
      <geom rgba="1 0 0 1" />
      <joint name="fingertip_36_x" type="slide" axis="1 0 0" limited="true" range="-0.03 0.03" />
      <joint name="fingertip_36_y" type="slide" axis="0 1 0" limited="true" range="-0.03 0.03" />
      <joint name="fingertip_36_z" type="slide" axis="0 0 1" limited="true" range="0.015 0.2" />
    </body>
    <body name="fingertip_37" pos="0.150000 0.216505 1.100000">
      <geom rgba="1 0 0 1" />
      <joint name="fingertip_37_x" type="slide" axis="1 0 0" limited="true" range="-0.03 0.03" />
      <joint name="fingertip_37_y" type="slide" axis="0 1 0" limited="true" range="-0.03 0.03" />
      <joint name="fingertip_37_z" type="slide" axis="0 0 1" limited="true" range="0.015 0.2" />
    </body>
    <body name="fingertip_38" pos="0.150000 0.259806 1.100000">
      <geom rgba="1 0 0 1" />
      <joint name="fingertip_38_x" type="slide" axis="1 0 0" limited="true" range="-0.03 0.03" />
      <joint name="fingertip_38_y" type="slide" axis="0 1 0" limited="true" range="-0.03 0.03" />
      <joint name="fingertip_38_z" type="slide" axis="0 0 1" limited="true" range="0.015 0.2" />
    </body>
    <body name="fingertip_39" pos="0.150000 0.303107 1.100000">
      <geom rgba="1 0 0 1" />
      <joint name="fingertip_39_x" type="slide" axis="1 0 0" limited="true" range="-0.03 0.03" />
      <joint name="fingertip_39_y" type="slide" axis="0 1 0" limited="true" range="-0.03 0.03" />
      <joint name="fingertip_39_z" type="slide" axis="0 0 1" limited="true" range="0.015 0.2" />
    </body>
    <body name="fingertip_40" pos="0.187500 -0.021650 1.100000">
      <geom rgba="1 0 0 1" />
      <joint name="fingertip_40_x" type="slide" axis="1 0 0" limited="true" range="-0.03 0.03" />
      <joint name="fingertip_40_y" type="slide" axis="0 1 0" limited="true" range="-0.03 0.03" />
      <joint name="fingertip_40_z" type="slide" axis="0 0 1" limited="true" range="0.015 0.2" />
    </body>
    <body name="fingertip_41" pos="0.187500 0.021651 1.100000">
      <geom rgba="1 0 0 1" />
      <joint name="fingertip_41_x" type="slide" axis="1 0 0" limited="true" range="-0.03 0.03" />
      <joint name="fingertip_41_y" type="slide" axis="0 1 0" limited="true" range="-0.03 0.03" />
      <joint name="fingertip_41_z" type="slide" axis="0 0 1" limited="true" range="0.015 0.2" />
    </body>
    <body name="fingertip_42" pos="0.187500 0.064952 1.100000">
      <geom rgba="1 0 0 1" />
      <joint name="fingertip_42_x" type="slide" axis="1 0 0" limited="true" range="-0.03 0.03" />
      <joint name="fingertip_42_y" type="slide" axis="0 1 0" limited="true" range="-0.03 0.03" />
      <joint name="fingertip_42_z" type="slide" axis="0 0 1" limited="true" range="0.015 0.2" />
    </body>
    <body name="fingertip_43" pos="0.187500 0.108253 1.100000">
      <geom rgba="1 0 0 1" />
      <joint name="fingertip_43_x" type="slide" axis="1 0 0" limited="true" range="-0.03 0.03" />
      <joint name="fingertip_43_y" type="slide" axis="0 1 0" limited="true" range="-0.03 0.03" />
      <joint name="fingertip_43_z" type="slide" axis="0 0 1" limited="true" range="0.015 0.2" />
    </body>
    <body name="fingertip_44" pos="0.187500 0.151554 1.100000">
      <geom rgba="1 0 0 1" />
      <joint name="fingertip_44_x" type="slide" axis="1 0 0" limited="true" range="-0.03 0.03" />
      <joint name="fingertip_44_y" type="slide" axis="0 1 0" limited="true" range="-0.03 0.03" />
      <joint name="fingertip_44_z" type="slide" axis="0 0 1" limited="true" range="0.015 0.2" />
    </body>
    <body name="fingertip_45" pos="0.187500 0.194855 1.100000">
      <geom rgba="1 0 0 1" />
      <joint name="fingertip_45_x" type="slide" axis="1 0 0" limited="true" range="-0.03 0.03" />
      <joint name="fingertip_45_y" type="slide" axis="0 1 0" limited="true" range="-0.03 0.03" />
      <joint name="fingertip_45_z" type="slide" axis="0 0 1" limited="true" range="0.015 0.2" />
    </body>
    <body name="fingertip_46" pos="0.187500 0.238156 1.100000">
      <geom rgba="1 0 0 1" />
      <joint name="fingertip_46_x" type="slide" axis="1 0 0" limited="true" range="-0.03 0.03" />
      <joint name="fingertip_46_y" type="slide" axis="0 1 0" limited="true" range="-0.03 0.03" />
      <joint name="fingertip_46_z" type="slide" axis="0 0 1" limited="true" range="0.015 0.2" />
    </body>
    <body name="fingertip_47" pos="0.187500 0.281457 1.100000">
      <geom rgba="1 0 0 1" />
      <joint name="fingertip_47_x" type="slide" axis="1 0 0" limited="true" range="-0.03 0.03" />
      <joint name="fingertip_47_y" type="slide" axis="0 1 0" limited="true" range="-0.03 0.03" />
      <joint name="fingertip_47_z" type="slide" axis="0 0 1" limited="true" range="0.015 0.2" />
    </body>
    <body name="fingertip_48" pos="0.225000 0.000000 1.100000">
      <geom rgba="1 0 0 1" />
      <joint name="fingertip_48_x" type="slide" axis="1 0 0" limited="true" range="-0.03 0.03" />
      <joint name="fingertip_48_y" type="slide" axis="0 1 0" limited="true" range="-0.03 0.03" />
      <joint name="fingertip_48_z" type="slide" axis="0 0 1" limited="true" range="0.015 0.2" />
    </body>
    <body name="fingertip_49" pos="0.225000 0.043301 1.100000">
      <geom rgba="1 0 0 1" />
      <joint name="fingertip_49_x" type="slide" axis="1 0 0" limited="true" range="-0.03 0.03" />
      <joint name="fingertip_49_y" type="slide" axis="0 1 0" limited="true" range="-0.03 0.03" />
      <joint name="fingertip_49_z" type="slide" axis="0 0 1" limited="true" range="0.015 0.2" />
    </body>
    <body name="fingertip_50" pos="0.225000 0.086602 1.100000">
      <geom rgba="1 0 0 1" />
      <joint name="fingertip_50_x" type="slide" axis="1 0 0" limited="true" range="-0.03 0.03" />
      <joint name="fingertip_50_y" type="slide" axis="0 1 0" limited="true" range="-0.03 0.03" />
      <joint name="fingertip_50_z" type="slide" axis="0 0 1" limited="true" range="0.015 0.2" />
    </body>
    <body name="fingertip_51" pos="0.225000 0.129903 1.100000">
      <geom rgba="1 0 0 1" />
      <joint name="fingertip_51_x" type="slide" axis="1 0 0" limited="true" range="-0.03 0.03" />
      <joint name="fingertip_51_y" type="slide" axis="0 1 0" limited="true" range="-0.03 0.03" />
      <joint name="fingertip_51_z" type="slide" axis="0 0 1" limited="true" range="0.015 0.2" />
    </body>
    <body name="fingertip_52" pos="0.225000 0.173204 1.100000">
      <geom rgba="1 0 0 1" />
      <joint name="fingertip_52_x" type="slide" axis="1 0 0" limited="true" range="-0.03 0.03" />
      <joint name="fingertip_52_y" type="slide" axis="0 1 0" limited="true" range="-0.03 0.03" />
      <joint name="fingertip_52_z" type="slide" axis="0 0 1" limited="true" range="0.015 0.2" />
    </body>
    <body name="fingertip_53" pos="0.225000 0.216505 1.100000">
      <geom rgba="1 0 0 1" />
      <joint name="fingertip_53_x" type="slide" axis="1 0 0" limited="true" range="-0.03 0.03" />
      <joint name="fingertip_53_y" type="slide" axis="0 1 0" limited="true" range="-0.03 0.03" />
      <joint name="fingertip_53_z" type="slide" axis="0 0 1" limited="true" range="0.015 0.2" />
    </body>
    <body name="fingertip_54" pos="0.225000 0.259806 1.100000">
      <geom rgba="1 0 0 1" />
      <joint name="fingertip_54_x" type="slide" axis="1 0 0" limited="true" range="-0.03 0.03" />
      <joint name="fingertip_54_y" type="slide" axis="0 1 0" limited="true" range="-0.03 0.03" />
      <joint name="fingertip_54_z" type="slide" axis="0 0 1" limited="true" range="0.015 0.2" />
    </body>
    <body name="fingertip_55" pos="0.225000 0.303107 1.100000">
      <geom rgba="1 0 0 1" />
      <joint name="fingertip_55_x" type="slide" axis="1 0 0" limited="true" range="-0.03 0.03" />
      <joint name="fingertip_55_y" type="slide" axis="0 1 0" limited="true" range="-0.03 0.03" />
      <joint name="fingertip_55_z" type="slide" axis="0 0 1" limited="true" range="0.015 0.2" />
    </body>
    <body name="fingertip_56" pos="0.262500 -0.021650 1.100000">
      <geom rgba="1 0 0 1" />
      <joint name="fingertip_56_x" type="slide" axis="1 0 0" limited="true" range="-0.03 0.03" />
      <joint name="fingertip_56_y" type="slide" axis="0 1 0" limited="true" range="-0.03 0.03" />
      <joint name="fingertip_56_z" type="slide" axis="0 0 1" limited="true" range="0.015 0.2" />
    </body>
    <body name="fingertip_57" pos="0.262500 0.021651 1.100000">
      <geom rgba="1 0 0 1" />
      <joint name="fingertip_57_x" type="slide" axis="1 0 0" limited="true" range="-0.03 0.03" />
      <joint name="fingertip_57_y" type="slide" axis="0 1 0" limited="true" range="-0.03 0.03" />
      <joint name="fingertip_57_z" type="slide" axis="0 0 1" limited="true" range="0.015 0.2" />
    </body>
    <body name="fingertip_58" pos="0.262500 0.064952 1.100000">
      <geom rgba="1 0 0 1" />
      <joint name="fingertip_58_x" type="slide" axis="1 0 0" limited="true" range="-0.03 0.03" />
      <joint name="fingertip_58_y" type="slide" axis="0 1 0" limited="true" range="-0.03 0.03" />
      <joint name="fingertip_58_z" type="slide" axis="0 0 1" limited="true" range="0.015 0.2" />
    </body>
    <body name="fingertip_59" pos="0.262500 0.108253 1.100000">
      <geom rgba="1 0 0 1" />
      <joint name="fingertip_59_x" type="slide" axis="1 0 0" limited="true" range="-0.03 0.03" />
      <joint name="fingertip_59_y" type="slide" axis="0 1 0" limited="true" range="-0.03 0.03" />
      <joint name="fingertip_59_z" type="slide" axis="0 0 1" limited="true" range="0.015 0.2" />
    </body>
    <body name="fingertip_60" pos="0.262500 0.151554 1.100000">
      <geom rgba="1 0 0 1" />
      <joint name="fingertip_60_x" type="slide" axis="1 0 0" limited="true" range="-0.03 0.03" />
      <joint name="fingertip_60_y" type="slide" axis="0 1 0" limited="true" range="-0.03 0.03" />
      <joint name="fingertip_60_z" type="slide" axis="0 0 1" limited="true" range="0.015 0.2" />
    </body>
    <body name="fingertip_61" pos="0.262500 0.194855 1.100000">
      <geom rgba="1 0 0 1" />
      <joint name="fingertip_61_x" type="slide" axis="1 0 0" limited="true" range="-0.03 0.03" />
      <joint name="fingertip_61_y" type="slide" axis="0 1 0" limited="true" range="-0.03 0.03" />
      <joint name="fingertip_61_z" type="slide" axis="0 0 1" limited="true" range="0.015 0.2" />
    </body>
    <body name="fingertip_62" pos="0.262500 0.238156 1.100000">
      <geom rgba="1 0 0 1" />
      <joint name="fingertip_62_x" type="slide" axis="1 0 0" limited="true" range="-0.03 0.03" />
      <joint name="fingertip_62_y" type="slide" axis="0 1 0" limited="true" range="-0.03 0.03" />
      <joint name="fingertip_62_z" type="slide" axis="0 0 1" limited="true" range="0.015 0.2" />
    </body>
    <body name="fingertip_63" pos="0.262500 0.281457 1.100000">
      <geom rgba="1 0 0 1" />
      <joint name="fingertip_63_x" type="slide" axis="1 0 0" limited="true" range="-0.03 0.03" />
      <joint name="fingertip_63_y" type="slide" axis="0 1 0" limited="true" range="-0.03 0.03" />
      <joint name="fingertip_63_z" type="slide" axis="0 0 1" limited="true" range="0.015 0.2" />
    </body>
    <body name="transparent_table" pos="0 0 0">
      <geom name="collision_geom" type="box" size="1 1 1" contype="1" conaffinity="1" condim="4" material="collision_material" />
      <geom name="visual_geom" type="box" size="0.15 0.15 0.015" contype="0" conaffinity="0" material="visual_material" />
    </body>
    <body name="block" pos="0.13125 1.1407285 1.0201" euler="90 0 0">
      <freejoint />
      <geom name="block" type="mesh" mesh="block" material="generic_obj" mass="0.05" condim="6" />
    </body>
    <body name="cross" pos="0.18125000000000002 1.1407285 1.0201" euler="90 0 0">
      <freejoint />
      <geom name="cross" type="mesh" mesh="cross" material="generic_obj" mass="0.05" condim="6" />
    </body>
    <body name="diamond" pos="0.23125 1.1407285 1.0201" euler="90 0 0">
      <freejoint />
      <geom name="diamond" type="mesh" mesh="diamond" material="generic_obj" mass="0.05" condim="6" />
    </body>
    <body name="hexagon" pos="0.28125 1.1407285 1.0201" euler="90 0 0">
      <freejoint />
      <geom name="hexagon" type="mesh" mesh="hexagon" material="generic_obj" mass="0.05" condim="6" />
    </body>
    <body name="star" pos="0.33125000000000004 1.1407285 1.0201" euler="90 0 0">
      <freejoint />
      <geom name="star" type="mesh" mesh="star" material="generic_obj" mass="0.05" condim="6" />
    </body>
    <body name="triangle" pos="0.38125 1.1407285 1.0201" euler="90 0 0">
      <freejoint />
      <geom name="triangle" type="mesh" mesh="triangle" material="generic_obj" mass="0.05" condim="6" />
    </body>
    <body name="parallelogram" pos="0.43125 1.1407285 1.0201" euler="90 0 0">
      <freejoint />
      <geom name="parallelogram" type="mesh" mesh="parallelogram" material="generic_obj" mass="0.05" condim="6" />
    </body>
    <body name="semicircle" pos="0.48125000000000007 1.1407285 1.0201" euler="90 0 0">
      <freejoint />
      <geom name="semicircle" type="mesh" mesh="semicircle" material="generic_obj" mass="0.05" condim="6" />
    </body>
    <body name="trapezium" pos="0.53125 1.1407285 1.0201" euler="90 0 0">
      <freejoint />
      <geom name="trapezium" type="mesh" mesh="trapezium" material="generic_obj" mass="0.05" condim="6" />
    </body>
    <body name="disc" pos="0.58125 1.1407285 1.0201" euler="90 0 0">
      <freejoint />
      <geom name="disc" type="mesh" mesh="disc" material="generic_obj" mass="0.05" condim="6" />
    </body>
  </worldbody>
  <actuator>
    <position name="act_fingertip_0_x" joint="fingertip_0_x" ctrllimited="true" ctrlrange="-0.03 0.03" kp="50" kv="20" />
    <position name="act_fingertip_0_y" joint="fingertip_0_y" ctrllimited="true" ctrlrange="-0.03 0.03" kp="50" kv="20" />
    <position name="act_fingertip_1_x" joint="fingertip_1_x" ctrllimited="true" ctrlrange="-0.03 0.03" kp="50" kv="20" />
    <position name="act_fingertip_1_y" joint="fingertip_1_y" ctrllimited="true" ctrlrange="-0.03 0.03" kp="50" kv="20" />
    <position name="act_fingertip_2_x" joint="fingertip_2_x" ctrllimited="true" ctrlrange="-0.03 0.03" kp="50" kv="20" />
    <position name="act_fingertip_2_y" joint="fingertip_2_y" ctrllimited="true" ctrlrange="-0.03 0.03" kp="50" kv="20" />
    <position name="act_fingertip_3_x" joint="fingertip_3_x" ctrllimited="true" ctrlrange="-0.03 0.03" kp="50" kv="20" />
    <position name="act_fingertip_3_y" joint="fingertip_3_y" ctrllimited="true" ctrlrange="-0.03 0.03" kp="50" kv="20" />
    <position name="act_fingertip_4_x" joint="fingertip_4_x" ctrllimited="true" ctrlrange="-0.03 0.03" kp="50" kv="20" />
    <position name="act_fingertip_4_y" joint="fingertip_4_y" ctrllimited="true" ctrlrange="-0.03 0.03" kp="50" kv="20" />
    <position name="act_fingertip_5_x" joint="fingertip_5_x" ctrllimited="true" ctrlrange="-0.03 0.03" kp="50" kv="20" />
    <position name="act_fingertip_5_y" joint="fingertip_5_y" ctrllimited="true" ctrlrange="-0.03 0.03" kp="50" kv="20" />
    <position name="act_fingertip_6_x" joint="fingertip_6_x" ctrllimited="true" ctrlrange="-0.03 0.03" kp="50" kv="20" />
    <position name="act_fingertip_6_y" joint="fingertip_6_y" ctrllimited="true" ctrlrange="-0.03 0.03" kp="50" kv="20" />
    <position name="act_fingertip_7_x" joint="fingertip_7_x" ctrllimited="true" ctrlrange="-0.03 0.03" kp="50" kv="20" />
    <position name="act_fingertip_7_y" joint="fingertip_7_y" ctrllimited="true" ctrlrange="-0.03 0.03" kp="50" kv="20" />
    <position name="act_fingertip_8_x" joint="fingertip_8_x" ctrllimited="true" ctrlrange="-0.03 0.03" kp="50" kv="20" />
    <position name="act_fingertip_8_y" joint="fingertip_8_y" ctrllimited="true" ctrlrange="-0.03 0.03" kp="50" kv="20" />
    <position name="act_fingertip_9_x" joint="fingertip_9_x" ctrllimited="true" ctrlrange="-0.03 0.03" kp="50" kv="20" />
    <position name="act_fingertip_9_y" joint="fingertip_9_y" ctrllimited="true" ctrlrange="-0.03 0.03" kp="50" kv="20" />
    <position name="act_fingertip_10_x" joint="fingertip_10_x" ctrllimited="true" ctrlrange="-0.03 0.03" kp="50" kv="20" />
    <position name="act_fingertip_10_y" joint="fingertip_10_y" ctrllimited="true" ctrlrange="-0.03 0.03" kp="50" kv="20" />
    <position name="act_fingertip_11_x" joint="fingertip_11_x" ctrllimited="true" ctrlrange="-0.03 0.03" kp="50" kv="20" />
    <position name="act_fingertip_11_y" joint="fingertip_11_y" ctrllimited="true" ctrlrange="-0.03 0.03" kp="50" kv="20" />
    <position name="act_fingertip_12_x" joint="fingertip_12_x" ctrllimited="true" ctrlrange="-0.03 0.03" kp="50" kv="20" />
    <position name="act_fingertip_12_y" joint="fingertip_12_y" ctrllimited="true" ctrlrange="-0.03 0.03" kp="50" kv="20" />
    <position name="act_fingertip_13_x" joint="fingertip_13_x" ctrllimited="true" ctrlrange="-0.03 0.03" kp="50" kv="20" />
    <position name="act_fingertip_13_y" joint="fingertip_13_y" ctrllimited="true" ctrlrange="-0.03 0.03" kp="50" kv="20" />
    <position name="act_fingertip_14_x" joint="fingertip_14_x" ctrllimited="true" ctrlrange="-0.03 0.03" kp="50" kv="20" />
    <position name="act_fingertip_14_y" joint="fingertip_14_y" ctrllimited="true" ctrlrange="-0.03 0.03" kp="50" kv="20" />
    <position name="act_fingertip_15_x" joint="fingertip_15_x" ctrllimited="true" ctrlrange="-0.03 0.03" kp="50" kv="20" />
    <position name="act_fingertip_15_y" joint="fingertip_15_y" ctrllimited="true" ctrlrange="-0.03 0.03" kp="50" kv="20" />
    <position name="act_fingertip_16_x" joint="fingertip_16_x" ctrllimited="true" ctrlrange="-0.03 0.03" kp="50" kv="20" />
    <position name="act_fingertip_16_y" joint="fingertip_16_y" ctrllimited="true" ctrlrange="-0.03 0.03" kp="50" kv="20" />
    <position name="act_fingertip_17_x" joint="fingertip_17_x" ctrllimited="true" ctrlrange="-0.03 0.03" kp="50" kv="20" />
    <position name="act_fingertip_17_y" joint="fingertip_17_y" ctrllimited="true" ctrlrange="-0.03 0.03" kp="50" kv="20" />
    <position name="act_fingertip_18_x" joint="fingertip_18_x" ctrllimited="true" ctrlrange="-0.03 0.03" kp="50" kv="20" />
    <position name="act_fingertip_18_y" joint="fingertip_18_y" ctrllimited="true" ctrlrange="-0.03 0.03" kp="50" kv="20" />
    <position name="act_fingertip_19_x" joint="fingertip_19_x" ctrllimited="true" ctrlrange="-0.03 0.03" kp="50" kv="20" />
    <position name="act_fingertip_19_y" joint="fingertip_19_y" ctrllimited="true" ctrlrange="-0.03 0.03" kp="50" kv="20" />
    <position name="act_fingertip_20_x" joint="fingertip_20_x" ctrllimited="true" ctrlrange="-0.03 0.03" kp="50" kv="20" />
    <position name="act_fingertip_20_y" joint="fingertip_20_y" ctrllimited="true" ctrlrange="-0.03 0.03" kp="50" kv="20" />
    <position name="act_fingertip_21_x" joint="fingertip_21_x" ctrllimited="true" ctrlrange="-0.03 0.03" kp="50" kv="20" />
    <position name="act_fingertip_21_y" joint="fingertip_21_y" ctrllimited="true" ctrlrange="-0.03 0.03" kp="50" kv="20" />
    <position name="act_fingertip_22_x" joint="fingertip_22_x" ctrllimited="true" ctrlrange="-0.03 0.03" kp="50" kv="20" />
    <position name="act_fingertip_22_y" joint="fingertip_22_y" ctrllimited="true" ctrlrange="-0.03 0.03" kp="50" kv="20" />
    <position name="act_fingertip_23_x" joint="fingertip_23_x" ctrllimited="true" ctrlrange="-0.03 0.03" kp="50" kv="20" />
    <position name="act_fingertip_23_y" joint="fingertip_23_y" ctrllimited="true" ctrlrange="-0.03 0.03" kp="50" kv="20" />
    <position name="act_fingertip_24_x" joint="fingertip_24_x" ctrllimited="true" ctrlrange="-0.03 0.03" kp="50" kv="20" />
    <position name="act_fingertip_24_y" joint="fingertip_24_y" ctrllimited="true" ctrlrange="-0.03 0.03" kp="50" kv="20" />
    <position name="act_fingertip_25_x" joint="fingertip_25_x" ctrllimited="true" ctrlrange="-0.03 0.03" kp="50" kv="20" />
    <position name="act_fingertip_25_y" joint="fingertip_25_y" ctrllimited="true" ctrlrange="-0.03 0.03" kp="50" kv="20" />
    <position name="act_fingertip_26_x" joint="fingertip_26_x" ctrllimited="true" ctrlrange="-0.03 0.03" kp="50" kv="20" />
    <position name="act_fingertip_26_y" joint="fingertip_26_y" ctrllimited="true" ctrlrange="-0.03 0.03" kp="50" kv="20" />
    <position name="act_fingertip_27_x" joint="fingertip_27_x" ctrllimited="true" ctrlrange="-0.03 0.03" kp="50" kv="20" />
    <position name="act_fingertip_27_y" joint="fingertip_27_y" ctrllimited="true" ctrlrange="-0.03 0.03" kp="50" kv="20" />
    <position name="act_fingertip_28_x" joint="fingertip_28_x" ctrllimited="true" ctrlrange="-0.03 0.03" kp="50" kv="20" />
    <position name="act_fingertip_28_y" joint="fingertip_28_y" ctrllimited="true" ctrlrange="-0.03 0.03" kp="50" kv="20" />
    <position name="act_fingertip_29_x" joint="fingertip_29_x" ctrllimited="true" ctrlrange="-0.03 0.03" kp="50" kv="20" />
    <position name="act_fingertip_29_y" joint="fingertip_29_y" ctrllimited="true" ctrlrange="-0.03 0.03" kp="50" kv="20" />
    <position name="act_fingertip_30_x" joint="fingertip_30_x" ctrllimited="true" ctrlrange="-0.03 0.03" kp="50" kv="20" />
    <position name="act_fingertip_30_y" joint="fingertip_30_y" ctrllimited="true" ctrlrange="-0.03 0.03" kp="50" kv="20" />
    <position name="act_fingertip_31_x" joint="fingertip_31_x" ctrllimited="true" ctrlrange="-0.03 0.03" kp="50" kv="20" />
    <position name="act_fingertip_31_y" joint="fingertip_31_y" ctrllimited="true" ctrlrange="-0.03 0.03" kp="50" kv="20" />
    <position name="act_fingertip_32_x" joint="fingertip_32_x" ctrllimited="true" ctrlrange="-0.03 0.03" kp="50" kv="20" />
    <position name="act_fingertip_32_y" joint="fingertip_32_y" ctrllimited="true" ctrlrange="-0.03 0.03" kp="50" kv="20" />
    <position name="act_fingertip_33_x" joint="fingertip_33_x" ctrllimited="true" ctrlrange="-0.03 0.03" kp="50" kv="20" />
    <position name="act_fingertip_33_y" joint="fingertip_33_y" ctrllimited="true" ctrlrange="-0.03 0.03" kp="50" kv="20" />
    <position name="act_fingertip_34_x" joint="fingertip_34_x" ctrllimited="true" ctrlrange="-0.03 0.03" kp="50" kv="20" />
    <position name="act_fingertip_34_y" joint="fingertip_34_y" ctrllimited="true" ctrlrange="-0.03 0.03" kp="50" kv="20" />
    <position name="act_fingertip_35_x" joint="fingertip_35_x" ctrllimited="true" ctrlrange="-0.03 0.03" kp="50" kv="20" />
    <position name="act_fingertip_35_y" joint="fingertip_35_y" ctrllimited="true" ctrlrange="-0.03 0.03" kp="50" kv="20" />
    <position name="act_fingertip_36_x" joint="fingertip_36_x" ctrllimited="true" ctrlrange="-0.03 0.03" kp="50" kv="20" />
    <position name="act_fingertip_36_y" joint="fingertip_36_y" ctrllimited="true" ctrlrange="-0.03 0.03" kp="50" kv="20" />
    <position name="act_fingertip_37_x" joint="fingertip_37_x" ctrllimited="true" ctrlrange="-0.03 0.03" kp="50" kv="20" />
    <position name="act_fingertip_37_y" joint="fingertip_37_y" ctrllimited="true" ctrlrange="-0.03 0.03" kp="50" kv="20" />
    <position name="act_fingertip_38_x" joint="fingertip_38_x" ctrllimited="true" ctrlrange="-0.03 0.03" kp="50" kv="20" />
    <position name="act_fingertip_38_y" joint="fingertip_38_y" ctrllimited="true" ctrlrange="-0.03 0.03" kp="50" kv="20" />
    <position name="act_fingertip_39_x" joint="fingertip_39_x" ctrllimited="true" ctrlrange="-0.03 0.03" kp="50" kv="20" />
    <position name="act_fingertip_39_y" joint="fingertip_39_y" ctrllimited="true" ctrlrange="-0.03 0.03" kp="50" kv="20" />
    <position name="act_fingertip_40_x" joint="fingertip_40_x" ctrllimited="true" ctrlrange="-0.03 0.03" kp="50" kv="20" />
    <position name="act_fingertip_40_y" joint="fingertip_40_y" ctrllimited="true" ctrlrange="-0.03 0.03" kp="50" kv="20" />
    <position name="act_fingertip_41_x" joint="fingertip_41_x" ctrllimited="true" ctrlrange="-0.03 0.03" kp="50" kv="20" />
    <position name="act_fingertip_41_y" joint="fingertip_41_y" ctrllimited="true" ctrlrange="-0.03 0.03" kp="50" kv="20" />
    <position name="act_fingertip_42_x" joint="fingertip_42_x" ctrllimited="true" ctrlrange="-0.03 0.03" kp="50" kv="20" />
    <position name="act_fingertip_42_y" joint="fingertip_42_y" ctrllimited="true" ctrlrange="-0.03 0.03" kp="50" kv="20" />
    <position name="act_fingertip_43_x" joint="fingertip_43_x" ctrllimited="true" ctrlrange="-0.03 0.03" kp="50" kv="20" />
    <position name="act_fingertip_43_y" joint="fingertip_43_y" ctrllimited="true" ctrlrange="-0.03 0.03" kp="50" kv="20" />
    <position name="act_fingertip_44_x" joint="fingertip_44_x" ctrllimited="true" ctrlrange="-0.03 0.03" kp="50" kv="20" />
    <position name="act_fingertip_44_y" joint="fingertip_44_y" ctrllimited="true" ctrlrange="-0.03 0.03" kp="50" kv="20" />
    <position name="act_fingertip_45_x" joint="fingertip_45_x" ctrllimited="true" ctrlrange="-0.03 0.03" kp="50" kv="20" />
    <position name="act_fingertip_45_y" joint="fingertip_45_y" ctrllimited="true" ctrlrange="-0.03 0.03" kp="50" kv="20" />
    <position name="act_fingertip_46_x" joint="fingertip_46_x" ctrllimited="true" ctrlrange="-0.03 0.03" kp="50" kv="20" />
    <position name="act_fingertip_46_y" joint="fingertip_46_y" ctrllimited="true" ctrlrange="-0.03 0.03" kp="50" kv="20" />
    <position name="act_fingertip_47_x" joint="fingertip_47_x" ctrllimited="true" ctrlrange="-0.03 0.03" kp="50" kv="20" />
    <position name="act_fingertip_47_y" joint="fingertip_47_y" ctrllimited="true" ctrlrange="-0.03 0.03" kp="50" kv="20" />
    <position name="act_fingertip_48_x" joint="fingertip_48_x" ctrllimited="true" ctrlrange="-0.03 0.03" kp="50" kv="20" />
    <position name="act_fingertip_48_y" joint="fingertip_48_y" ctrllimited="true" ctrlrange="-0.03 0.03" kp="50" kv="20" />
    <position name="act_fingertip_49_x" joint="fingertip_49_x" ctrllimited="true" ctrlrange="-0.03 0.03" kp="50" kv="20" />
    <position name="act_fingertip_49_y" joint="fingertip_49_y" ctrllimited="true" ctrlrange="-0.03 0.03" kp="50" kv="20" />
    <position name="act_fingertip_50_x" joint="fingertip_50_x" ctrllimited="true" ctrlrange="-0.03 0.03" kp="50" kv="20" />
    <position name="act_fingertip_50_y" joint="fingertip_50_y" ctrllimited="true" ctrlrange="-0.03 0.03" kp="50" kv="20" />
    <position name="act_fingertip_51_x" joint="fingertip_51_x" ctrllimited="true" ctrlrange="-0.03 0.03" kp="50" kv="20" />
    <position name="act_fingertip_51_y" joint="fingertip_51_y" ctrllimited="true" ctrlrange="-0.03 0.03" kp="50" kv="20" />
    <position name="act_fingertip_52_x" joint="fingertip_52_x" ctrllimited="true" ctrlrange="-0.03 0.03" kp="50" kv="20" />
    <position name="act_fingertip_52_y" joint="fingertip_52_y" ctrllimited="true" ctrlrange="-0.03 0.03" kp="50" kv="20" />
    <position name="act_fingertip_53_x" joint="fingertip_53_x" ctrllimited="true" ctrlrange="-0.03 0.03" kp="50" kv="20" />
    <position name="act_fingertip_53_y" joint="fingertip_53_y" ctrllimited="true" ctrlrange="-0.03 0.03" kp="50" kv="20" />
    <position name="act_fingertip_54_x" joint="fingertip_54_x" ctrllimited="true" ctrlrange="-0.03 0.03" kp="50" kv="20" />
    <position name="act_fingertip_54_y" joint="fingertip_54_y" ctrllimited="true" ctrlrange="-0.03 0.03" kp="50" kv="20" />
    <position name="act_fingertip_55_x" joint="fingertip_55_x" ctrllimited="true" ctrlrange="-0.03 0.03" kp="50" kv="20" />
    <position name="act_fingertip_55_y" joint="fingertip_55_y" ctrllimited="true" ctrlrange="-0.03 0.03" kp="50" kv="20" />
    <position name="act_fingertip_56_x" joint="fingertip_56_x" ctrllimited="true" ctrlrange="-0.03 0.03" kp="50" kv="20" />
    <position name="act_fingertip_56_y" joint="fingertip_56_y" ctrllimited="true" ctrlrange="-0.03 0.03" kp="50" kv="20" />
    <position name="act_fingertip_57_x" joint="fingertip_57_x" ctrllimited="true" ctrlrange="-0.03 0.03" kp="50" kv="20" />
    <position name="act_fingertip_57_y" joint="fingertip_57_y" ctrllimited="true" ctrlrange="-0.03 0.03" kp="50" kv="20" />
    <position name="act_fingertip_58_x" joint="fingertip_58_x" ctrllimited="true" ctrlrange="-0.03 0.03" kp="50" kv="20" />
    <position name="act_fingertip_58_y" joint="fingertip_58_y" ctrllimited="true" ctrlrange="-0.03 0.03" kp="50" kv="20" />
    <position name="act_fingertip_59_x" joint="fingertip_59_x" ctrllimited="true" ctrlrange="-0.03 0.03" kp="50" kv="20" />
    <position name="act_fingertip_59_y" joint="fingertip_59_y" ctrllimited="true" ctrlrange="-0.03 0.03" kp="50" kv="20" />
    <position name="act_fingertip_60_x" joint="fingertip_60_x" ctrllimited="true" ctrlrange="-0.03 0.03" kp="50" kv="20" />
    <position name="act_fingertip_60_y" joint="fingertip_60_y" ctrllimited="true" ctrlrange="-0.03 0.03" kp="50" kv="20" />
    <position name="act_fingertip_61_x" joint="fingertip_61_x" ctrllimited="true" ctrlrange="-0.03 0.03" kp="50" kv="20" />
    <position name="act_fingertip_61_y" joint="fingertip_61_y" ctrllimited="true" ctrlrange="-0.03 0.03" kp="50" kv="20" />
    <position name="act_fingertip_62_x" joint="fingertip_62_x" ctrllimited="true" ctrlrange="-0.03 0.03" kp="50" kv="20" />
    <position name="act_fingertip_62_y" joint="fingertip_62_y" ctrllimited="true" ctrlrange="-0.03 0.03" kp="50" kv="20" />
    <position name="act_fingertip_63_x" joint="fingertip_63_x" ctrllimited="true" ctrlrange="-0.03 0.03" kp="50" kv="20" />
    <position name="act_fingertip_63_y" joint="fingertip_63_y" ctrllimited="true" ctrlrange="-0.03 0.03" kp="50" kv="20" />
  </actuator>
</mujoco>